Workbook

Sheet Excel Project (2)
A1: GRADE TRACKER
A2: Name of the Student: | D2: Jayashree
A3: Branch: | D3: Computer Science
A4: College: | D4: Anna University
S5: Grade Rating:
A6: Year | B6: Semester | C6: Theory/ Practical | D6: Course code | E6: Subject | F6: Internal Marks | G6: Exam Marks | H6: Total Marks | I6: Percentage of marks | J6: Letter Grade | K6: Grade Points (A) | L6: Credit for the subject (B) | M6: Sum of the credits for the semester ( C) | N6: GPA for the semester [D=Σ(A*B)/C] | O6: Credit for all the Semesters (Cumulative) (F) | P6: CGPA at the end of each Semester =Σ(D*C)/F | Q6: Remarks | S6: Marks Range | U6: Letter Grade | V6: Grade Points | W6: Performance
F7: Out of : 50 | G7: Out of :50 | H7: Out of :100 | S7: 91 | T7: 100 | U7: O | V7: 10 | W7: Outstanding
A8: 1 | B8: 1 | C8: Theory | D8: HS8151 | E8: =VLOOKUP(D8,'Course data'!$C$4:$H$65,2,FALSE) -> Technical English I | F8: 38 | G8: 35 | H8: =F8+G8 -> 73 | I8: =IF(F8<>"",AVERAGE(H8:H17),"") -> 61.7 | J8: =IF(F8<>"",IF(AND(H8>=$S$7,H8<=$T$7),$U$7,IF(AND(H8>=$S$8,H8<=$T$8),$U$8,IF(AND(H8>=$S$9,H8<=$T$9),$U$9,IF(AND(H8>=$S$10,H8<=$T$10),$U$10,IF(AND(H8>=$S$11,H8<=$T$11),$U$11,IF(AND(H8>=$S$12,H8<=$T$12),$U$12,0)))))),"") -> A | K8: =IF(F8<>"",IF(AND(H8>=$S$7,H8<=$T$7),$V$7,IF(AND(H8>=$S$8,H8<=$T$8),$V$8,IF(AND(H8>=$S$9,H8<=$T$9),$V$9,IF(AND(H8>=$S$10,H8<=$T$10),$V$10,IF(AND(H8>=$S$11,H8<=$T$11),$V$11,IF(AND(H8>=$S$12,H8<=$T$12),$V$12,0)))))),"") -> 8 | L8: =IF(F8<>"",4,"") -> 4 | M8: =IF(F8<>"",SUM(L8:L17),"") -> 26 | N8: =IF(F8<>"",SUMPRODUCT(K8:K17,L8:L17)/M8,"") -> 6 | O8: =IF(F8<>"",M8,"") -> 26 | P8: =IF(F8<>"",SUMPRODUCT(M8:M17,N8:N17)/O8,"") -> 6 | S8: 81 | T8: 90 | U8: A+ | V8: 9 | W8: Excellent
D9: MA8151 | E9: =VLOOKUP(D9,'Course data'!$C$4:$H$65,2,FALSE) -> Mathematics I | F9: 26 | G9: 38 | H9: =F9+G9 -> 64 | J9: =IF(F9<>"",IF(AND(H9>=$S$7,H9<=$T$7),$U$7,IF(AND(H9>=$S$8,H9<=$T$8),$U$8,IF(AND(H9>=$S$9,H9<=$T$9),$U$9,IF(AND(H9>=$S$10,H9<=$T$10),$U$10,IF(AND(H9>=$S$11,H9<=$T$11),$U$11,IF(AND(H9>=$S$12,H9<=$T$12),$U$12,0)))))),"") -> B+ | K9: =IF(F9<>"",IF(AND(H9>=$S$7,H9<=$T$7),$V$7,IF(AND(H9>=$S$8,H9<=$T$8),$V$8,IF(AND(H9>=$S$9,H9<=$T$9),$V$9,IF(AND(H9>=$S$10,H9<=$T$10),$V$10,IF(AND(H9>=$S$11,H9<=$T$11),$V$11,IF(AND(H9>=$S$12,H9<=$T$12),$V$12,0)))))),"") -> 7 | L9: =IF(F9<>"",3,"") -> 3 | S9: 71 | T9: 80 | U9: A | V9: 8 | W9: Very Good
D10: PH8151 | E10: =VLOOKUP(D10,'Course data'!$C$4:$H$65,2,FALSE) -> Engineering Physics | F10: 40 | G10: 38 | H10: =F10+G10 -> 78 | J10: =IF(F10<>"",IF(AND(H10>=$S$7,H10<=$T$7),$U$7,IF(AND(H10>=$S$8,H10<=$T$8),$U$8,IF(AND(H10>=$S$9,H10<=$T$9),$U$9,IF(AND(H10>=$S$10,H10<=$T$10),$U$10,IF(AND(H10>=$S$11,H10<=$T$11),$U$11,IF(AND(H10>=$S$12,H10<=$T$12),$U$12,0)))))),"") -> A | K10: =IF(F10<>"",IF(AND(H10>=$S$7,H10<=$T$7),$V$7,IF(AND(H10>=$S$8,H10<=$T$8),$V$8,IF(AND(H10>=$S$9,H10<=$T$9),$V$9,IF(AND(H10>=$S$10,H10<=$T$10),$V$10,IF(AND(H10>=$S$11,H10<=$T$11),$V$11,IF(AND(H10>=$S$12,H10<=$T$12),$V$12,0)))))),"") -> 8 | L10: =IF(F10<>"",3,"") -> 3 | S10: 61 | T10: 70 | U10: B+ | V10: 7 | W10: Good
D11: CY8151 | E11: =VLOOKUP(D11,'Course data'!$C$4:$H$65,2,FALSE) -> Engineering Chemistry | F11: 30 | G11: 25 | H11: =F11+G11 -> 55 | J11: =IF(F11<>"",IF(AND(H11>=$S$7,H11<=$T$7),$U$7,IF(AND(H11>=$S$8,H11<=$T$8),$U$8,IF(AND(H11>=$S$9,H11<=$T$9),$U$9,IF(AND(H11>=$S$10,H11<=$T$10),$U$10,IF(AND(H11>=$S$11,H11<=$T$11),$U$11,IF(AND(H11>=$S$12,H11<=$T$12),$U$12,0)))))),"") -> B | K11: =IF(F11<>"",IF(AND(H11>=$S$7,H11<=$T$7),$V$7,IF(AND(H11>=$S$8,H11<=$T$8),$V$8,IF(AND(H11>=$S$9,H11<=$T$9),$V$9,IF(AND(H11>=$S$10,H11<=$T$10),$V$10,IF(AND(H11>=$S$11,H11<=$T$11),$V$11,IF(AND(H11>=$S$12,H11<=$T$12),$V$12,0)))))),"") -> 6 | L11: =IF(F11<>"",3,"") -> 3 | S11: 51 | T11: 60 | U11: B | V11: 6 | W11: Average
D12: GE8152 | E12: =VLOOKUP(D12,'Course data'!$C$4:$H$65,2,FALSE) -> Engineering Graphics | F12: 35 | G12: 30 | H12: =F12+G12 -> 65 | J12: =IF(F12<>"",IF(AND(H12>=$S$7,H12<=$T$7),$U$7,IF(AND(H12>=$S$8,H12<=$T$8),$U$8,IF(AND(H12>=$S$9,H12<=$T$9),$U$9,IF(AND(H12>=$S$10,H12<=$T$10),$U$10,IF(AND(H12>=$S$11,H12<=$T$11),$U$11,IF(AND(H12>=$S$12,H12<=$T$12),$U$12,0)))))),"") -> B+ | K12: =IF(F12<>"",IF(AND(H12>=$S$7,H12<=$T$7),$V$7,IF(AND(H12>=$S$8,H12<=$T$8),$V$8,IF(AND(H12>=$S$9,H12<=$T$9),$V$9,IF(AND(H12>=$S$10,H12<=$T$10),$V$10,IF(AND(H12>=$S$11,H12<=$T$11),$V$11,IF(AND(H12>=$S$12,H12<=$T$12),$V$12,0)))))),"") -> 7 | L12: =IF(F12<>"",4,"") -> 4 | S12: 50 | T12: 0 | U12: RA | V12: 0 | W12: Reappearance Registration
D13: GE8151 | E13: =VLOOKUP(D13,'Course data'!$C$4:$H$65,2,FALSE) -> Computing Techniques | F13: 19 | G13: 25 | H13: =F13+G13 -> 44 | J13: =IF(F13<>"",IF(AND(H13>=$S$7,H13<=$T$7),$U$7,IF(AND(H13>=$S$8,H13<=$T$8),$U$8,IF(AND(H13>=$S$9,H13<=$T$9),$U$9,IF(AND(H13>=$S$10,H13<=$T$10),$U$10,IF(AND(H13>=$S$11,H13<=$T$11),$U$11,IF(AND(H13>=$S$12,H13<=$T$12),$U$12,0)))))),"") -> 0 | K13: =IF(F13<>"",IF(AND(H13>=$S$7,H13<=$T$7),$V$7,IF(AND(H13>=$S$8,H13<=$T$8),$V$8,IF(AND(H13>=$S$9,H13<=$T$9),$V$9,IF(AND(H13>=$S$10,H13<=$T$10),$V$10,IF(AND(H13>=$S$11,H13<=$T$11),$V$11,IF(AND(H13>=$S$12,H13<=$T$12),$V$12,0)))))),"") -> 0 | L13: =IF(F13<>"",3,"") -> 3 | S13: - | U13: SA | V13: 0 | W13: Shortage of Attendance
C14: Practical | D14: PH8161 | E14: =VLOOKUP(D14,'Course data'!$C$4:$H$65,2,FALSE) -> Physics Laboratory | F14: 23 | G14: 27 | H14: =F14+G14 -> 50 | J14: =IF(F14<>"",IF(AND(H14>=$S$7,H14<=$T$7),$U$7,IF(AND(H14>=$S$8,H14<=$T$8),$U$8,IF(AND(H14>=$S$9,H14<=$T$9),$U$9,IF(AND(H14>=$S$10,H14<=$T$10),$U$10,IF(AND(H14>=$S$11,H14<=$T$11),$U$11,IF(AND(H14>=$S$12,H14<=$T$12),$U$12,0)))))),"") -> 0 | K14: =IF(F14<>"",IF(AND(H14>=$S$7,H14<=$T$7),$V$7,IF(AND(H14>=$S$8,H14<=$T$8),$V$8,IF(AND(H14>=$S$9,H14<=$T$9),$V$9,IF(AND(H14>=$S$10,H14<=$T$10),$V$10,IF(AND(H14>=$S$11,H14<=$T$11),$V$11,IF(AND(H14>=$S$12,H14<=$T$12),$V$12,0)))))),"") -> 0 | L14: =IF(F14<>"",1,"") -> 1 | S14: - | U14: W | V14: 0 | W14: Withdrawal
D15: CY8161 | E15: =VLOOKUP(D15,'Course data'!$C$4:$H$65,2,FALSE) -> Chemistry Laboratory | F15: 38 | G15: 30 | H15: =F15+G15 -> 68 | J15: =IF(F15<>"",IF(AND(H15>=$S$7,H15<=$T$7),$U$7,IF(AND(H15>=$S$8,H15<=$T$8),$U$8,IF(AND(H15>=$S$9,H15<=$T$9),$U$9,IF(AND(H15>=$S$10,H15<=$T$10),$U$10,IF(AND(H15>=$S$11,H15<=$T$11),$U$11,IF(AND(H15>=$S$12,H15<=$T$12),$U$12,0)))))),"") -> B+ | K15: =IF(F15<>"",IF(AND(H15>=$S$7,H15<=$T$7),$V$7,IF(AND(H15>=$S$8,H15<=$T$8),$V$8,IF(AND(H15>=$S$9,H15<=$T$9),$V$9,IF(AND(H15>=$S$10,H15<=$T$10),$V$10,IF(AND(H15>=$S$11,H15<=$T$11),$V$11,IF(AND(H15>=$S$12,H15<=$T$12),$V$12,0)))))),"") -> 7 | L15: =IF(F15<>"",1,"") -> 1
D16: GE8162 | E16: =VLOOKUP(D16,'Course data'!$C$4:$H$65,2,FALSE) -> Engineering Practices Laboratory | F16: 30 | G16: 25 | H16: =F16+G16 -> 55 | J16: =IF(F16<>"",IF(AND(H16>=$S$7,H16<=$T$7),$U$7,IF(AND(H16>=$S$8,H16<=$T$8),$U$8,IF(AND(H16>=$S$9,H16<=$T$9),$U$9,IF(AND(H16>=$S$10,H16<=$T$10),$U$10,IF(AND(H16>=$S$11,H16<=$T$11),$U$11,IF(AND(H16>=$S$12,H16<=$T$12),$U$12,0)))))),"") -> B | K16: =IF(F16<>"",IF(AND(H16>=$S$7,H16<=$T$7),$V$7,IF(AND(H16>=$S$8,H16<=$T$8),$V$8,IF(AND(H16>=$S$9,H16<=$T$9),$V$9,IF(AND(H16>=$S$10,H16<=$T$10),$V$10,IF(AND(H16>=$S$11,H16<=$T$11),$V$11,IF(AND(H16>=$S$12,H16<=$T$12),$V$12,0)))))),"") -> 6 | L16: =IF(F16<>"",2,"") -> 2 | S16: GPA = | V16: Grade Points Average
D17: GE8161 | E17: =VLOOKUP(D17,'Course data'!$C$4:$H$65,2,FALSE) -> Computer Practice Laboratory | F17: 28 | G17: 37 | H17: =F17+G17 -> 65 | J17: =IF(F17<>"",IF(AND(H17>=$S$7,H17<=$T$7),$U$7,IF(AND(H17>=$S$8,H17<=$T$8),$U$8,IF(AND(H17>=$S$9,H17<=$T$9),$U$9,IF(AND(H17>=$S$10,H17<=$T$10),$U$10,IF(AND(H17>=$S$11,H17<=$T$11),$U$11,IF(AND(H17>=$S$12,H17<=$T$12),$U$12,0)))))),"") -> B+ | K17: =IF(F17<>"",IF(AND(H17>=$S$7,H17<=$T$7),$V$7,IF(AND(H17>=$S$8,H17<=$T$8),$V$8,IF(AND(H17>=$S$9,H17<=$T$9),$V$9,IF(AND(H17>=$S$10,H17<=$T$10),$V$10,IF(AND(H17>=$S$11,H17<=$T$11),$V$11,IF(AND(H17>=$S$12,H17<=$T$12),$V$12,0)))))),"") -> 7 | L17: =IF(F17<>"",2,"") -> 2 | S17: CGPA = | V17: Cumulative Grade Points Average
B18: 2 | C18: Theory | D18: HS8251 | E18: =VLOOKUP(D18,'Course data'!$C$4:$H$65,2,FALSE) -> Technical English II | F18: 38 | G18: 34 | H18: =F18+G18 -> 72 | I18: =IF(F18<>"",AVERAGE(H18:H25),"") -> 69.625 | J18: =IF(F18<>"",IF(AND(H18>=$S$7,H18<=$T$7),$U$7,IF(AND(H18>=$S$8,H18<=$T$8),$U$8,IF(AND(H18>=$S$9,H18<=$T$9),$U$9,IF(AND(H18>=$S$10,H18<=$T$10),$U$10,IF(AND(H18>=$S$11,H18<=$T$11),$U$11,IF(AND(H18>=$S$12,H18<=$T$12),$U$12,0)))))),"") -> A | K18: =IF(F18<>"",IF(AND(H18>=$S$7,H18<=$T$7),$V$7,IF(AND(H18>=$S$8,H18<=$T$8),$V$8,IF(AND(H18>=$S$9,H18<=$T$9),$V$9,IF(AND(H18>=$S$10,H18<=$T$10),$V$10,IF(AND(H18>=$S$11,H18<=$T$11),$V$11,IF(AND(H18>=$S$12,H18<=$T$12),$V$12,0)))))),"") -> 8 | L18: =IF(F18<>"",4,"") -> 4 | M18: =IF(F18<>"",SUM(L18:L25),"") -> 24 | N18: =IF(F18<>"",SUMPRODUCT(K18:K25,L18:L25)/M18,"") -> 6.5 | O18: =IF(F18<>"",SUM(M8:M25),"") -> 50 | P18: =IF(F18<>"",SUMPRODUCT(M8:M25,N8:N25)/O18,"") -> 6.24
D19: MA8251 | E19: =VLOOKUP(D19,'Course data'!$C$4:$H$65,2,FALSE) -> Mathematics II | F19: 21 | G19: 28 | H19: =F19+G19 -> 49 | J19: =IF(F19<>"",IF(AND(H19>=$S$7,H19<=$T$7),$U$7,IF(AND(H19>=$S$8,H19<=$T$8),$U$8,IF(AND(H19>=$S$9,H19<=$T$9),$U$9,IF(AND(H19>=$S$10,H19<=$T$10),$U$10,IF(AND(H19>=$S$11,H19<=$T$11),$U$11,IF(AND(H19>=$S$12,H19<=$T$12),$U$12,0)))))),"") -> 0 | K19: =IF(F19<>"",IF(AND(H19>=$S$7,H19<=$T$7),$V$7,IF(AND(H19>=$S$8,H19<=$T$8),$V$8,IF(AND(H19>=$S$9,H19<=$T$9),$V$9,IF(AND(H19>=$S$10,H19<=$T$10),$V$10,IF(AND(H19>=$S$11,H19<=$T$11),$V$11,IF(AND(H19>=$S$12,H19<=$T$12),$V$12,0)))))),"") -> 0 | L19: =IF(F19<>"",4,"") -> 4
D20: PH8253 | E20: =VLOOKUP(D20,'Course data'!$C$4:$H$65,2,FALSE) -> Physics for Information Science | F20: 29 | G20: 35 | H20: =F20+G20 -> 64 | J20: =IF(F20<>"",IF(AND(H20>=$S$7,H20<=$T$7),$U$7,IF(AND(H20>=$S$8,H20<=$T$8),$U$8,IF(AND(H20>=$S$9,H20<=$T$9),$U$9,IF(AND(H20>=$S$10,H20<=$T$10),$U$10,IF(AND(H20>=$S$11,H20<=$T$11),$U$11,IF(AND(H20>=$S$12,H20<=$T$12),$U$12,0)))))),"") -> B+ | K20: =IF(F20<>"",IF(AND(H20>=$S$7,H20<=$T$7),$V$7,IF(AND(H20>=$S$8,H20<=$T$8),$V$8,IF(AND(H20>=$S$9,H20<=$T$9),$V$9,IF(AND(H20>=$S$10,H20<=$T$10),$V$10,IF(AND(H20>=$S$11,H20<=$T$11),$V$11,IF(AND(H20>=$S$12,H20<=$T$12),$V$12,0)))))),"") -> 7 | L20: =IF(F20<>"",3,"") -> 3
D21: CS8202 | E21: =VLOOKUP(D21,'Course data'!$C$4:$H$65,2,FALSE) -> Principles of Computer Engineering | F21: 49 | G21: 47 | H21: =F21+G21 -> 96 | J21: =IF(F21<>"",IF(AND(H21>=$S$7,H21<=$T$7),$U$7,IF(AND(H21>=$S$8,H21<=$T$8),$U$8,IF(AND(H21>=$S$9,H21<=$T$9),$U$9,IF(AND(H21>=$S$10,H21<=$T$10),$U$10,IF(AND(H21>=$S$11,H21<=$T$11),$U$11,IF(AND(H21>=$S$12,H21<=$T$12),$U$12,0)))))),"") -> O | K21: =IF(F21<>"",IF(AND(H21>=$S$7,H21<=$T$7),$V$7,IF(AND(H21>=$S$8,H21<=$T$8),$V$8,IF(AND(H21>=$S$9,H21<=$T$9),$V$9,IF(AND(H21>=$S$10,H21<=$T$10),$V$10,IF(AND(H21>=$S$11,H21<=$T$11),$V$11,IF(AND(H21>=$S$12,H21<=$T$12),$V$12,0)))))),"") -> 10 | L21: =IF(F21<>"",3,"") -> 3
D22: CS8203 | E22: =VLOOKUP(D22,'Course data'!$C$4:$H$65,2,FALSE) -> Programming using C++ | F22: 30 | G22: 25 | H22: =F22+G22 -> 55 | J22: =IF(F22<>"",IF(AND(H22>=$S$7,H22<=$T$7),$U$7,IF(AND(H22>=$S$8,H22<=$T$8),$U$8,IF(AND(H22>=$S$9,H22<=$T$9),$U$9,IF(AND(H22>=$S$10,H22<=$T$10),$U$10,IF(AND(H22>=$S$11,H22<=$T$11),$U$11,IF(AND(H22>=$S$12,H22<=$T$12),$U$12,0)))))),"") -> B | K22: =IF(F22<>"",IF(AND(H22>=$S$7,H22<=$T$7),$V$7,IF(AND(H22>=$S$8,H22<=$T$8),$V$8,IF(AND(H22>=$S$9,H22<=$T$9),$V$9,IF(AND(H22>=$S$10,H22<=$T$10),$V$10,IF(AND(H22>=$S$11,H22<=$T$11),$V$11,IF(AND(H22>=$S$12,H22<=$T$12),$V$12,0)))))),"") -> 6 | L22: =IF(F22<>"",3,"") -> 3
D23: CS8201 | E23: =VLOOKUP(D23,'Course data'!$C$4:$H$65,2,FALSE) -> Digital Principles and System Design | F23: 47 | G23: 42 | H23: =F23+G23 -> 89 | J23: =IF(F23<>"",IF(AND(H23>=$S$7,H23<=$T$7),$U$7,IF(AND(H23>=$S$8,H23<=$T$8),$U$8,IF(AND(H23>=$S$9,H23<=$T$9),$U$9,IF(AND(H23>=$S$10,H23<=$T$10),$U$10,IF(AND(H23>=$S$11,H23<=$T$11),$U$11,IF(AND(H23>=$S$12,H23<=$T$12),$U$12,0)))))),"") -> A+ | K23: =IF(F23<>"",IF(AND(H23>=$S$7,H23<=$T$7),$V$7,IF(AND(H23>=$S$8,H23<=$T$8),$V$8,IF(AND(H23>=$S$9,H23<=$T$9),$V$9,IF(AND(H23>=$S$10,H23<=$T$10),$V$10,IF(AND(H23>=$S$11,H23<=$T$11),$V$11,IF(AND(H23>=$S$12,H23<=$T$12),$V$12,0)))))),"") -> 9 | L23: =IF(F23<>"",3,"") -> 3
C24: Practical | D24: CS8212 | E24: =VLOOKUP(D24,'Course data'!$C$4:$H$65,2,FALSE) -> Programming Laboratory | F24: 50 | G24: 25 | H24: =F24+G24 -> 75 | J24: =IF(F24<>"",IF(AND(H24>=$S$7,H24<=$T$7),$U$7,IF(AND(H24>=$S$8,H24<=$T$8),$U$8,IF(AND(H24>=$S$9,H24<=$T$9),$U$9,IF(AND(H24>=$S$10,H24<=$T$10),$U$10,IF(AND(H24>=$S$11,H24<=$T$11),$U$11,IF(AND(H24>=$S$12,H24<=$T$12),$U$12,0)))))),"") -> A | K24: =IF(F24<>"",IF(AND(H24>=$S$7,H24<=$T$7),$V$7,IF(AND(H24>=$S$8,H24<=$T$8),$V$8,IF(AND(H24>=$S$9,H24<=$T$9),$V$9,IF(AND(H24>=$S$10,H24<=$T$10),$V$10,IF(AND(H24>=$S$11,H24<=$T$11),$V$11,IF(AND(H24>=$S$12,H24<=$T$12),$V$12,0)))))),"") -> 8 | L24: =IF(F24<>"",2,"") -> 2
D25: CS8211 | E25: =VLOOKUP(D25,'Course data'!$C$4:$H$65,2,FALSE) -> Digital Laboratory | F25: 35 | G25: 22 | H25: =F25+G25 -> 57 | J25: =IF(F25<>"",IF(AND(H25>=$S$7,H25<=$T$7),$U$7,IF(AND(H25>=$S$8,H25<=$T$8),$U$8,IF(AND(H25>=$S$9,H25<=$T$9),$U$9,IF(AND(H25>=$S$10,H25<=$T$10),$U$10,IF(AND(H25>=$S$11,H25<=$T$11),$U$11,IF(AND(H25>=$S$12,H25<=$T$12),$U$12,0)))))),"") -> B | K25: =IF(F25<>"",IF(AND(H25>=$S$7,H25<=$T$7),$V$7,IF(AND(H25>=$S$8,H25<=$T$8),$V$8,IF(AND(H25>=$S$9,H25<=$T$9),$V$9,IF(AND(H25>=$S$10,H25<=$T$10),$V$10,IF(AND(H25>=$S$11,H25<=$T$11),$V$11,IF(AND(H25>=$S$12,H25<=$T$12),$V$12,0)))))),"") -> 6 | L25: =IF(F25<>"",2,"") -> 2
A26: 2 | B26: 3 | C26: Theory | D26: MA8351 | E26: =VLOOKUP(D26,'Course data'!$C$4:$H$65,2,FALSE) -> Algebra & Number Theory | F26: 19 | G26: 25 | H26: =F26+G26 -> 44 | I26: =IF(F26<>"",AVERAGE(H26:H33),"") -> 78.875 | J26: =IF(F26<>"",IF(AND(H26>=$S$7,H26<=$T$7),$U$7,IF(AND(H26>=$S$8,H26<=$T$8),$U$8,IF(AND(H26>=$S$9,H26<=$T$9),$U$9,IF(AND(H26>=$S$10,H26<=$T$10),$U$10,IF(AND(H26>=$S$11,H26<=$T$11),$U$11,IF(AND(H26>=$S$12,H26<=$T$12),$U$12,0)))))),"") -> 0 | K26: =IF(F26<>"",IF(AND(H26>=$S$7,H26<=$T$7),$V$7,IF(AND(H26>=$S$8,H26<=$T$8),$V$8,IF(AND(H26>=$S$9,H26<=$T$9),$V$9,IF(AND(H26>=$S$10,H26<=$T$10),$V$10,IF(AND(H26>=$S$11,H26<=$T$11),$V$11,IF(AND(H26>=$S$12,H26<=$T$12),$V$12,0)))))),"") -> 0 | L26: =IF(F26<>"",4,"") -> 4 | M26: =IF(F26<>"",SUM(L26:L33),"") -> 24 | N26: =IF(F26<>"",SUMPRODUCT(K26:K33,L26:L33)/M26,"") -> 7.4583333 | O26: =IF(F26<>"",SUM(M8:M33),"") -> 74 | P26: =IF(F26<>"",SUMPRODUCT(M8:M33,N8:N33)/O26,"") -> 6.6351351
D27: EC8303 | E27: =VLOOKUP(D27,'Course data'!$C$4:$H$65,2,FALSE) -> Electronic Devices and Circuits for Computer Engineers | F27: 38 | G27: 43 | H27: =F27+G27 -> 81 | J27: =IF(F27<>"",IF(AND(H27>=$S$7,H27<=$T$7),$U$7,IF(AND(H27>=$S$8,H27<=$T$8),$U$8,IF(AND(H27>=$S$9,H27<=$T$9),$U$9,IF(AND(H27>=$S$10,H27<=$T$10),$U$10,IF(AND(H27>=$S$11,H27<=$T$11),$U$11,IF(AND(H27>=$S$12,H27<=$T$12),$U$12,0)))))),"") -> A+ | K27: =IF(F27<>"",IF(AND(H27>=$S$7,H27<=$T$7),$V$7,IF(AND(H27>=$S$8,H27<=$T$8),$V$8,IF(AND(H27>=$S$9,H27<=$T$9),$V$9,IF(AND(H27>=$S$10,H27<=$T$10),$V$10,IF(AND(H27>=$S$11,H27<=$T$11),$V$11,IF(AND(H27>=$S$12,H27<=$T$12),$V$12,0)))))),"") -> 9 | L27: =IF(F27<>"",3,"") -> 3
D28: CS8302 | E28: =VLOOKUP(D28,'Course data'!$C$4:$H$65,2,FALSE) -> Data Structures | F28: 45 | G28: 49 | H28: =F28+G28 -> 94 | J28: =IF(F28<>"",IF(AND(H28>=$S$7,H28<=$T$7),$U$7,IF(AND(H28>=$S$8,H28<=$T$8),$U$8,IF(AND(H28>=$S$9,H28<=$T$9),$U$9,IF(AND(H28>=$S$10,H28<=$T$10),$U$10,IF(AND(H28>=$S$11,H28<=$T$11),$U$11,IF(AND(H28>=$S$12,H28<=$T$12),$U$12,0)))))),"") -> O | K28: =IF(F28<>"",IF(AND(H28>=$S$7,H28<=$T$7),$V$7,IF(AND(H28>=$S$8,H28<=$T$8),$V$8,IF(AND(H28>=$S$9,H28<=$T$9),$V$9,IF(AND(H28>=$S$10,H28<=$T$10),$V$10,IF(AND(H28>=$S$11,H28<=$T$11),$V$11,IF(AND(H28>=$S$12,H28<=$T$12),$V$12,0)))))),"") -> 10 | L28: =IF(F28<>"",3,"") -> 3
D29: CS8303 | E29: =VLOOKUP(D29,'Course data'!$C$4:$H$65,2,FALSE) -> Database Management Systems | F29: 35 | G29: 27 | H29: =F29+G29 -> 62 | J29: =IF(F29<>"",IF(AND(H29>=$S$7,H29<=$T$7),$U$7,IF(AND(H29>=$S$8,H29<=$T$8),$U$8,IF(AND(H29>=$S$9,H29<=$T$9),$U$9,IF(AND(H29>=$S$10,H29<=$T$10),$U$10,IF(AND(H29>=$S$11,H29<=$T$11),$U$11,IF(AND(H29>=$S$12,H29<=$T$12),$U$12,0)))))),"") -> B+ | K29: =IF(F29<>"",IF(AND(H29>=$S$7,H29<=$T$7),$V$7,IF(AND(H29>=$S$8,H29<=$T$8),$V$8,IF(AND(H29>=$S$9,H29<=$T$9),$V$9,IF(AND(H29>=$S$10,H29<=$T$10),$V$10,IF(AND(H29>=$S$11,H29<=$T$11),$V$11,IF(AND(H29>=$S$12,H29<=$T$12),$V$12,0)))))),"") -> 7 | L29: =IF(F29<>"",3,"") -> 3
D30: GE8351 | E30: =VLOOKUP(D30,'Course data'!$C$4:$H$65,2,FALSE) -> Environmental Science & Engineering | F30: 41 | G30: 43 | H30: =F30+G30 -> 84 | J30: =IF(F30<>"",IF(AND(H30>=$S$7,H30<=$T$7),$U$7,IF(AND(H30>=$S$8,H30<=$T$8),$U$8,IF(AND(H30>=$S$9,H30<=$T$9),$U$9,IF(AND(H30>=$S$10,H30<=$T$10),$U$10,IF(AND(H30>=$S$11,H30<=$T$11),$U$11,IF(AND(H30>=$S$12,H30<=$T$12),$U$12,0)))))),"") -> A+ | K30: =IF(F30<>"",IF(AND(H30>=$S$7,H30<=$T$7),$V$7,IF(AND(H30>=$S$8,H30<=$T$8),$V$8,IF(AND(H30>=$S$9,H30<=$T$9),$V$9,IF(AND(H30>=$S$10,H30<=$T$10),$V$10,IF(AND(H30>=$S$11,H30<=$T$11),$V$11,IF(AND(H30>=$S$12,H30<=$T$12),$V$12,0)))))),"") -> 9 | L30: =IF(F30<>"",3,"") -> 3
D31: CS8301 | E31: =VLOOKUP(D31,'Course data'!$C$4:$H$65,2,FALSE) -> Computer Architecture | F31: 47 | G31: 35 | H31: =F31+G31 -> 82 | J31: =IF(F31<>"",IF(AND(H31>=$S$7,H31<=$T$7),$U$7,IF(AND(H31>=$S$8,H31<=$T$8),$U$8,IF(AND(H31>=$S$9,H31<=$T$9),$U$9,IF(AND(H31>=$S$10,H31<=$T$10),$U$10,IF(AND(H31>=$S$11,H31<=$T$11),$U$11,IF(AND(H31>=$S$12,H31<=$T$12),$U$12,0)))))),"") -> A+ | K31: =IF(F31<>"",IF(AND(H31>=$S$7,H31<=$T$7),$V$7,IF(AND(H31>=$S$8,H31<=$T$8),$V$8,IF(AND(H31>=$S$9,H31<=$T$9),$V$9,IF(AND(H31>=$S$10,H31<=$T$10),$V$10,IF(AND(H31>=$S$11,H31<=$T$11),$V$11,IF(AND(H31>=$S$12,H31<=$T$12),$V$12,0)))))),"") -> 9 | L31: =IF(F31<>"",4,"") -> 4
C32: Practical | D32: CS8312 | E32: =VLOOKUP(D32,'Course data'!$C$4:$H$65,2,FALSE) -> Database Management Systems Laboratory | F32: 43 | G32: 45 | H32: =F32+G32 -> 88 | J32: =IF(F32<>"",IF(AND(H32>=$S$7,H32<=$T$7),$U$7,IF(AND(H32>=$S$8,H32<=$T$8),$U$8,IF(AND(H32>=$S$9,H32<=$T$9),$U$9,IF(AND(H32>=$S$10,H32<=$T$10),$U$10,IF(AND(H32>=$S$11,H32<=$T$11),$U$11,IF(AND(H32>=$S$12,H32<=$T$12),$U$12,0)))))),"") -> A+ | K32: =IF(F32<>"",IF(AND(H32>=$S$7,H32<=$T$7),$V$7,IF(AND(H32>=$S$8,H32<=$T$8),$V$8,IF(AND(H32>=$S$9,H32<=$T$9),$V$9,IF(AND(H32>=$S$10,H32<=$T$10),$V$10,IF(AND(H32>=$S$11,H32<=$T$11),$V$11,IF(AND(H32>=$S$12,H32<=$T$12),$V$12,0)))))),"") -> 9 | L32: =IF(F32<>"",2,"") -> 2
D33: CS8311 | E33: =VLOOKUP(D33,'Course data'!$C$4:$H$65,2,FALSE) -> Data Structures Laboratory | F33: 49 | G33: 47 | H33: =F33+G33 -> 96 | J33: =IF(F33<>"",IF(AND(H33>=$S$7,H33<=$T$7),$U$7,IF(AND(H33>=$S$8,H33<=$T$8),$U$8,IF(AND(H33>=$S$9,H33<=$T$9),$U$9,IF(AND(H33>=$S$10,H33<=$T$10),$U$10,IF(AND(H33>=$S$11,H33<=$T$11),$U$11,IF(AND(H33>=$S$12,H33<=$T$12),$U$12,0)))))),"") -> O | K33: =IF(F33<>"",IF(AND(H33>=$S$7,H33<=$T$7),$V$7,IF(AND(H33>=$S$8,H33<=$T$8),$V$8,IF(AND(H33>=$S$9,H33<=$T$9),$V$9,IF(AND(H33>=$S$10,H33<=$T$10),$V$10,IF(AND(H33>=$S$11,H33<=$T$11),$V$11,IF(AND(H33>=$S$12,H33<=$T$12),$V$12,0)))))),"") -> 10 | L33: =IF(F33<>"",2,"") -> 2
B34: 4 | C34: Theory | D34: EE8407 | E34: =VLOOKUP(D34,'Course data'!$C$4:$H$65,2,FALSE) -> Electrical Engineering and Control Systems | F34: 50 | G34: 50 | H34: =F34+G34 -> 100 | I34: =IF(F34<>"",AVERAGE(H34:H41),"") -> 74.5 | J34: =IF(F34<>"",IF(AND(H34>=$S$7,H34<=$T$7),$U$7,IF(AND(H34>=$S$8,H34<=$T$8),$U$8,IF(AND(H34>=$S$9,H34<=$T$9),$U$9,IF(AND(H34>=$S$10,H34<=$T$10),$U$10,IF(AND(H34>=$S$11,H34<=$T$11),$U$11,IF(AND(H34>=$S$12,H34<=$T$12),$U$12,0)))))),"") -> O | K34: =IF(F34<>"",IF(AND(H34>=$S$7,H34<=$T$7),$V$7,IF(AND(H34>=$S$8,H34<=$T$8),$V$8,IF(AND(H34>=$S$9,H34<=$T$9),$V$9,IF(AND(H34>=$S$10,H34<=$T$10),$V$10,IF(AND(H34>=$S$11,H34<=$T$11),$V$11,IF(AND(H34>=$S$12,H34<=$T$12),$V$12,0)))))),"") -> 10 | L34: =IF(F34<>"",3,"") -> 3 | M34: =IF(F34<>"",SUM(L34:L41),"") -> 25 | N34: =IF(F34<>"",SUMPRODUCT(K34:K41,L34:L41)/M34,"") -> 7.68 | O34: =IF(F34<>"",SUM(M8:M41),"") -> 99 | P34: =IF(F34<>"",SUMPRODUCT(M8:M41,N8:N41)/O34,"") -> 6.8989899
D35: CS8401 | E35: =VLOOKUP(D35,'Course data'!$C$4:$H$65,2,FALSE) -> Design & Analysis of Algorithms | F35: 43 | G35: 45 | H35: =F35+G35 -> 88 | J35: =IF(F35<>"",IF(AND(H35>=$S$7,H35<=$T$7),$U$7,IF(AND(H35>=$S$8,H35<=$T$8),$U$8,IF(AND(H35>=$S$9,H35<=$T$9),$U$9,IF(AND(H35>=$S$10,H35<=$T$10),$U$10,IF(AND(H35>=$S$11,H35<=$T$11),$U$11,IF(AND(H35>=$S$12,H35<=$T$12),$U$12,0)))))),"") -> A+ | K35: =IF(F35<>"",IF(AND(H35>=$S$7,H35<=$T$7),$V$7,IF(AND(H35>=$S$8,H35<=$T$8),$V$8,IF(AND(H35>=$S$9,H35<=$T$9),$V$9,IF(AND(H35>=$S$10,H35<=$T$10),$V$10,IF(AND(H35>=$S$11,H35<=$T$11),$V$11,IF(AND(H35>=$S$12,H35<=$T$12),$V$12,0)))))),"") -> 9 | L35: =IF(F35<>"",4,"") -> 4
D36: CS8451 | E36: =VLOOKUP(D36,'Course data'!$C$4:$H$65,2,FALSE) -> Operating Systems | F36: 39 | G36: 38 | H36: =F36+G36 -> 77 | J36: =IF(F36<>"",IF(AND(H36>=$S$7,H36<=$T$7),$U$7,IF(AND(H36>=$S$8,H36<=$T$8),$U$8,IF(AND(H36>=$S$9,H36<=$T$9),$U$9,IF(AND(H36>=$S$10,H36<=$T$10),$U$10,IF(AND(H36>=$S$11,H36<=$T$11),$U$11,IF(AND(H36>=$S$12,H36<=$T$12),$U$12,0)))))),"") -> A | K36: =IF(F36<>"",IF(AND(H36>=$S$7,H36<=$T$7),$V$7,IF(AND(H36>=$S$8,H36<=$T$8),$V$8,IF(AND(H36>=$S$9,H36<=$T$9),$V$9,IF(AND(H36>=$S$10,H36<=$T$10),$V$10,IF(AND(H36>=$S$11,H36<=$T$11),$V$11,IF(AND(H36>=$S$12,H36<=$T$12),$V$12,0)))))),"") -> 8 | L36: =IF(F36<>"",3,"") -> 3
D37: CS8402 | E37: =VLOOKUP(D37,'Course data'!$C$4:$H$65,2,FALSE) -> Java & Internet Programming | F37: 38 | G37: 35 | H37: =F37+G37 -> 73 | J37: =IF(F37<>"",IF(AND(H37>=$S$7,H37<=$T$7),$U$7,IF(AND(H37>=$S$8,H37<=$T$8),$U$8,IF(AND(H37>=$S$9,H37<=$T$9),$U$9,IF(AND(H37>=$S$10,H37<=$T$10),$U$10,IF(AND(H37>=$S$11,H37<=$T$11),$U$11,IF(AND(H37>=$S$12,H37<=$T$12),$U$12,0)))))),"") -> A | K37: =IF(F37<>"",IF(AND(H37>=$S$7,H37<=$T$7),$V$7,IF(AND(H37>=$S$8,H37<=$T$8),$V$8,IF(AND(H37>=$S$9,H37<=$T$9),$V$9,IF(AND(H37>=$S$10,H37<=$T$10),$V$10,IF(AND(H37>=$S$11,H37<=$T$11),$V$11,IF(AND(H37>=$S$12,H37<=$T$12),$V$12,0)))))),"") -> 8 | L37: =IF(F37<>"",4,"") -> 4
D38: MA8354 | E38: =VLOOKUP(D38,'Course data'!$C$4:$H$65,2,FALSE) -> Probability & Queueing Theory | F38: 49 | G38: 37 | H38: =F38+G38 -> 86 | J38: =IF(F38<>"",IF(AND(H38>=$S$7,H38<=$T$7),$U$7,IF(AND(H38>=$S$8,H38<=$T$8),$U$8,IF(AND(H38>=$S$9,H38<=$T$9),$U$9,IF(AND(H38>=$S$10,H38<=$T$10),$U$10,IF(AND(H38>=$S$11,H38<=$T$11),$U$11,IF(AND(H38>=$S$12,H38<=$T$12),$U$12,0)))))),"") -> A+ | K38: =IF(F38<>"",IF(AND(H38>=$S$7,H38<=$T$7),$V$7,IF(AND(H38>=$S$8,H38<=$T$8),$V$8,IF(AND(H38>=$S$9,H38<=$T$9),$V$9,IF(AND(H38>=$S$10,H38<=$T$10),$V$10,IF(AND(H38>=$S$11,H38<=$T$11),$V$11,IF(AND(H38>=$S$12,H38<=$T$12),$V$12,0)))))),"") -> 9 | L38: =IF(F38<>"",4,"") -> 4
D39: CS8452 | E39: =VLOOKUP(D39,'Course data'!$C$4:$H$65,2,FALSE) -> Software Engineering | F39: 30 | G39: 25 | H39: =F39+G39 -> 55 | J39: =IF(F39<>"",IF(AND(H39>=$S$7,H39<=$T$7),$U$7,IF(AND(H39>=$S$8,H39<=$T$8),$U$8,IF(AND(H39>=$S$9,H39<=$T$9),$U$9,IF(AND(H39>=$S$10,H39<=$T$10),$U$10,IF(AND(H39>=$S$11,H39<=$T$11),$U$11,IF(AND(H39>=$S$12,H39<=$T$12),$U$12,0)))))),"") -> B | K39: =IF(F39<>"",IF(AND(H39>=$S$7,H39<=$T$7),$V$7,IF(AND(H39>=$S$8,H39<=$T$8),$V$8,IF(AND(H39>=$S$9,H39<=$T$9),$V$9,IF(AND(H39>=$S$10,H39<=$T$10),$V$10,IF(AND(H39>=$S$11,H39<=$T$11),$V$11,IF(AND(H39>=$S$12,H39<=$T$12),$V$12,0)))))),"") -> 6 | L39: =IF(F39<>"",3,"") -> 3
C40: Practical | D40: CS8411 | E40: =VLOOKUP(D40,'Course data'!$C$4:$H$65,2,FALSE) -> Java & Internet Programming Laboratory | F40: 33 | G40: 40 | H40: =F40+G40 -> 73 | J40: =IF(F40<>"",IF(AND(H40>=$S$7,H40<=$T$7),$U$7,IF(AND(H40>=$S$8,H40<=$T$8),$U$8,IF(AND(H40>=$S$9,H40<=$T$9),$U$9,IF(AND(H40>=$S$10,H40<=$T$10),$U$10,IF(AND(H40>=$S$11,H40<=$T$11),$U$11,IF(AND(H40>=$S$12,H40<=$T$12),$U$12,0)))))),"") -> A | K40: =IF(F40<>"",IF(AND(H40>=$S$7,H40<=$T$7),$V$7,IF(AND(H40>=$S$8,H40<=$T$8),$V$8,IF(AND(H40>=$S$9,H40<=$T$9),$V$9,IF(AND(H40>=$S$10,H40<=$T$10),$V$10,IF(AND(H40>=$S$11,H40<=$T$11),$V$11,IF(AND(H40>=$S$12,H40<=$T$12),$V$12,0)))))),"") -> 8 | L40: =IF(F40<>"",2,"") -> 2
...

Sheet Excel Project
A1: GRADE TRACKER
A2: Name of the Student:
A3: Branch: | D3: Computer Science
A4: College: | D4: Anna University
S5: Grade Rating:
A6: Year | B6: Semester | C6: Theory/ Practical | D6: Course code | E6: Subject | F6: Internal Marks | G6: Exam Marks | H6: Total Marks | I6: Percentage of marks | J6: Letter Grade | K6: Grade Points (A) | L6: Credit for the subject (B) | M6: Sum of the credits for the semester ( C) | N6: GPA for the semester [D=Σ(A*B)/C] | O6: Credit for all the Semesters (Cumulative) (F) | P6: CGPA at the end of the Semester =Σ(D*C)/F | Q6: Remarks | S6: Marks Range | U6: Letter Grade | V6: Grade Points | W6: Performance
F7: Out of : 50 | G7: Out of :50 | H7: Out of :100 | S7: 91 | T7: 100 | U7: O | V7: 10 | W7: Outstanding
A8: 1 | B8: 1 | C8: Theory | D8: HS8151 | E8: =VLOOKUP(D8,'Course data'!$C$4:$H$65,2,FALSE) -> Technical English I | F8: 38 | G8: 35 | H8: =F8+G8 -> 73 | I8: =AVERAGE(H8:H17) -> 61.7 | J8: =IF(AND(H8>=$S$7,H8<=$T$7),$U$7,IF(AND(H8>=$S$8,H8<=$T$8),$U$8,IF(AND(H8>=$S$9,H8<=$T$9),$U$9,IF(AND(H8>=$S$10,H8<=$T$10),$U$10,IF(AND(H8>=$S$11,H8<=$T$11),$U$11,IF(AND(H8>=$S$12,H8<=$T$12),$U$12,0)))))) -> A | K8: =IF(AND(H8>=$S$7,H8<=$T$7),$V$7,IF(AND(H8>=$S$8,H8<=$T$8),$V$8,IF(AND(H8>=$S$9,H8<=$T$9),$V$9,IF(AND(H8>=$S$10,H8<=$T$10),$V$10,IF(AND(H8>=$S$11,H8<=$T$11),$V$11,IF(AND(H8>=$S$12,H8<=$T$12),$V$12,0)))))) -> 8 | L8: 4 | M8: =SUM(L8:L17) -> 27 | N8: =IF(F8<>"",SUMPRODUCT(K8:K17,L8:L17)/M8,"") -> 6.037037 | O8: =M8 -> 27 | P8: =SUMPRODUCT(M8:M17,N8:N17)/O8 -> 6.037037 | S8: 81 | T8: 90 | U8: A+ | V8: 9 | W8: Excellent
D9: MA8151 | E9: =VLOOKUP(D9,'Course data'!$C$4:$H$65,2,FALSE) -> Mathematics I | F9: 26 | G9: 38 | H9: =F9+G9 -> 64 | J9: =IF(AND(H9>=$S$7,H9<=$T$7),$U$7,IF(AND(H9>=$S$8,H9<=$T$8),$U$8,IF(AND(H9>=$S$9,H9<=$T$9),$U$9,IF(AND(H9>=$S$10,H9<=$T$10),$U$10,IF(AND(H9>=$S$11,H9<=$T$11),$U$11,IF(AND(H9>=$S$12,H9<=$T$12),$U$12,0)))))) -> B+ | K9: =IF(AND(H9>=$S$7,H9<=$T$7),$V$7,IF(AND(H9>=$S$8,H9<=$T$8),$V$8,IF(AND(H9>=$S$9,H9<=$T$9),$V$9,IF(AND(H9>=$S$10,H9<=$T$10),$V$10,IF(AND(H9>=$S$11,H9<=$T$11),$V$11,IF(AND(H9>=$S$12,H9<=$T$12),$V$12,0)))))) -> 7 | L9: 4 | S9: 71 | T9: 80 | U9: A | V9: 8 | W9: Very Good
D10: PH8151 | E10: =VLOOKUP(D10,'Course data'!$C$4:$H$65,2,FALSE) -> Engineering Physics | F10: 40 | G10: 38 | H10: =F10+G10 -> 78 | J10: =IF(AND(H10>=$S$7,H10<=$T$7),$U$7,IF(AND(H10>=$S$8,H10<=$T$8),$U$8,IF(AND(H10>=$S$9,H10<=$T$9),$U$9,IF(AND(H10>=$S$10,H10<=$T$10),$U$10,IF(AND(H10>=$S$11,H10<=$T$11),$U$11,IF(AND(H10>=$S$12,H10<=$T$12),$U$12,0)))))) -> A | K10: =IF(AND(H10>=$S$7,H10<=$T$7),$V$7,IF(AND(H10>=$S$8,H10<=$T$8),$V$8,IF(AND(H10>=$S$9,H10<=$T$9),$V$9,IF(AND(H10>=$S$10,H10<=$T$10),$V$10,IF(AND(H10>=$S$11,H10<=$T$11),$V$11,IF(AND(H10>=$S$12,H10<=$T$12),$V$12,0)))))) -> 8 | L10: 3 | S10: 61 | T10: 70 | U10: B+ | V10: 7 | W10: Good
D11: CY8151 | E11: =VLOOKUP(D11,'Course data'!$C$4:$H$65,2,FALSE) -> Engineering Chemistry | F11: 30 | G11: 25 | H11: =F11+G11 -> 55 | J11: =IF(AND(H11>=$S$7,H11<=$T$7),$U$7,IF(AND(H11>=$S$8,H11<=$T$8),$U$8,IF(AND(H11>=$S$9,H11<=$T$9),$U$9,IF(AND(H11>=$S$10,H11<=$T$10),$U$10,IF(AND(H11>=$S$11,H11<=$T$11),$U$11,IF(AND(H11>=$S$12,H11<=$T$12),$U$12,0)))))) -> B | K11: =IF(AND(H11>=$S$7,H11<=$T$7),$V$7,IF(AND(H11>=$S$8,H11<=$T$8),$V$8,IF(AND(H11>=$S$9,H11<=$T$9),$V$9,IF(AND(H11>=$S$10,H11<=$T$10),$V$10,IF(AND(H11>=$S$11,H11<=$T$11),$V$11,IF(AND(H11>=$S$12,H11<=$T$12),$V$12,0)))))) -> 6 | L11: 3 | S11: 51 | T11: 60 | U11: B | V11: 6 | W11: Average
D12: GE8152 | E12: =VLOOKUP(D12,'Course data'!$C$4:$H$65,2,FALSE) -> Engineering Graphics | F12: 35 | G12: 30 | H12: =F12+G12 -> 65 | J12: =IF(AND(H12>=$S$7,H12<=$T$7),$U$7,IF(AND(H12>=$S$8,H12<=$T$8),$U$8,IF(AND(H12>=$S$9,H12<=$T$9),$U$9,IF(AND(H12>=$S$10,H12<=$T$10),$U$10,IF(AND(H12>=$S$11,H12<=$T$11),$U$11,IF(AND(H12>=$S$12,H12<=$T$12),$U$12,0)))))) -> B+ | K12: =IF(AND(H12>=$S$7,H12<=$T$7),$V$7,IF(AND(H12>=$S$8,H12<=$T$8),$V$8,IF(AND(H12>=$S$9,H12<=$T$9),$V$9,IF(AND(H12>=$S$10,H12<=$T$10),$V$10,IF(AND(H12>=$S$11,H12<=$T$11),$V$11,IF(AND(H12>=$S$12,H12<=$T$12),$V$12,0)))))) -> 7 | L12: 4 | S12: 50 | T12: 0 | U12: RA | V12: 0 | W12: Reappearance Registration
D13: GE8151 | E13: =VLOOKUP(D13,'Course data'!$C$4:$H$65,2,FALSE) -> Computing Techniques | F13: 19 | G13: 25 | H13: =F13+G13 -> 44 | J13: =IF(AND(H13>=$S$7,H13<=$T$7),$U$7,IF(AND(H13>=$S$8,H13<=$T$8),$U$8,IF(AND(H13>=$S$9,H13<=$T$9),$U$9,IF(AND(H13>=$S$10,H13<=$T$10),$U$10,IF(AND(H13>=$S$11,H13<=$T$11),$U$11,IF(AND(H13>=$S$12,H13<=$T$12),$U$12,0)))))) -> 0 | K13: =IF(AND(H13>=$S$7,H13<=$T$7),$V$7,IF(AND(H13>=$S$8,H13<=$T$8),$V$8,IF(AND(H13>=$S$9,H13<=$T$9),$V$9,IF(AND(H13>=$S$10,H13<=$T$10),$V$10,IF(AND(H13>=$S$11,H13<=$T$11),$V$11,IF(AND(H13>=$S$12,H13<=$T$12),$V$12,0)))))) -> 0 | L13: 3 | S13: - | U13: SA | V13: 0 | W13: Shortage of Attendance
C14: Practical | D14: PH8161 | E14: =VLOOKUP(D14,'Course data'!$C$4:$H$65,2,FALSE) -> Physics Laboratory | F14: 23 | G14: 27 | H14: =F14+G14 -> 50 | J14: =IF(AND(H14>=$S$7,H14<=$T$7),$U$7,IF(AND(H14>=$S$8,H14<=$T$8),$U$8,IF(AND(H14>=$S$9,H14<=$T$9),$U$9,IF(AND(H14>=$S$10,H14<=$T$10),$U$10,IF(AND(H14>=$S$11,H14<=$T$11),$U$11,IF(AND(H14>=$S$12,H14<=$T$12),$U$12,0)))))) -> 0 | K14: =IF(AND(H14>=$S$7,H14<=$T$7),$V$7,IF(AND(H14>=$S$8,H14<=$T$8),$V$8,IF(AND(H14>=$S$9,H14<=$T$9),$V$9,IF(AND(H14>=$S$10,H14<=$T$10),$V$10,IF(AND(H14>=$S$11,H14<=$T$11),$V$11,IF(AND(H14>=$S$12,H14<=$T$12),$V$12,0)))))) -> 0 | L14: 1 | S14: - | U14: W | V14: 0 | W14: Withdrawal
D15: CY8161 | E15: =VLOOKUP(D15,'Course data'!$C$4:$H$65,2,FALSE) -> Chemistry Laboratory | F15: 38 | G15: 30 | H15: =F15+G15 -> 68 | J15: =IF(AND(H15>=$S$7,H15<=$T$7),$U$7,IF(AND(H15>=$S$8,H15<=$T$8),$U$8,IF(AND(H15>=$S$9,H15<=$T$9),$U$9,IF(AND(H15>=$S$10,H15<=$T$10),$U$10,IF(AND(H15>=$S$11,H15<=$T$11),$U$11,IF(AND(H15>=$S$12,H15<=$T$12),$U$12,0)))))) -> B+ | K15: =IF(AND(H15>=$S$7,H15<=$T$7),$V$7,IF(AND(H15>=$S$8,H15<=$T$8),$V$8,IF(AND(H15>=$S$9,H15<=$T$9),$V$9,IF(AND(H15>=$S$10,H15<=$T$10),$V$10,IF(AND(H15>=$S$11,H15<=$T$11),$V$11,IF(AND(H15>=$S$12,H15<=$T$12),$V$12,0)))))) -> 7 | L15: 1
D16: GE8162 | E16: =VLOOKUP(D16,'Course data'!$C$4:$H$65,2,FALSE) -> Engineering Practices Laboratory | F16: 30 | G16: 25 | H16: =F16+G16 -> 55 | J16: =IF(AND(H16>=$S$7,H16<=$T$7),$U$7,IF(AND(H16>=$S$8,H16<=$T$8),$U$8,IF(AND(H16>=$S$9,H16<=$T$9),$U$9,IF(AND(H16>=$S$10,H16<=$T$10),$U$10,IF(AND(H16>=$S$11,H16<=$T$11),$U$11,IF(AND(H16>=$S$12,H16<=$T$12),$U$12,0)))))) -> B | K16: =IF(AND(H16>=$S$7,H16<=$T$7),$V$7,IF(AND(H16>=$S$8,H16<=$T$8),$V$8,IF(AND(H16>=$S$9,H16<=$T$9),$V$9,IF(AND(H16>=$S$10,H16<=$T$10),$V$10,IF(AND(H16>=$S$11,H16<=$T$11),$V$11,IF(AND(H16>=$S$12,H16<=$T$12),$V$12,0)))))) -> 6 | L16: 2 | S16: GPA = | V16: Grade Points Average
D17: GE8161 | E17: =VLOOKUP(D17,'Course data'!$C$4:$H$65,2,FALSE) -> Computer Practice Laboratory | F17: 28 | G17: 37 | H17: =F17+G17 -> 65 | J17: =IF(AND(H17>=$S$7,H17<=$T$7),$U$7,IF(AND(H17>=$S$8,H17<=$T$8),$U$8,IF(AND(H17>=$S$9,H17<=$T$9),$U$9,IF(AND(H17>=$S$10,H17<=$T$10),$U$10,IF(AND(H17>=$S$11,H17<=$T$11),$U$11,IF(AND(H17>=$S$12,H17<=$T$12),$U$12,0)))))) -> B+ | K17: =IF(AND(H17>=$S$7,H17<=$T$7),$V$7,IF(AND(H17>=$S$8,H17<=$T$8),$V$8,IF(AND(H17>=$S$9,H17<=$T$9),$V$9,IF(AND(H17>=$S$10,H17<=$T$10),$V$10,IF(AND(H17>=$S$11,H17<=$T$11),$V$11,IF(AND(H17>=$S$12,H17<=$T$12),$V$12,0)))))) -> 7 | L17: 2 | S17: CGPA = | V17: Cumulative Grade Points Average
B18: 2 | C18: Theory | D18: HS8251 | E18: =VLOOKUP(D18,'Course data'!$C$4:$H$65,2,FALSE) -> Technical English II | F18: 38 | G18: 34 | H18: =F18+G18 -> 72 | I18: =AVERAGE(H18:H25) -> 69.625 | J18: =IF(AND(H18>=$S$7,H18<=$T$7),$U$7,IF(AND(H18>=$S$8,H18<=$T$8),$U$8,IF(AND(H18>=$S$9,H18<=$T$9),$U$9,IF(AND(H18>=$S$10,H18<=$T$10),$U$10,IF(AND(H18>=$S$11,H18<=$T$11),$U$11,IF(AND(H18>=$S$12,H18<=$T$12),$U$12,0)))))) -> A | K18: =IF(AND(H18>=$S$7,H18<=$T$7),$V$7,IF(AND(H18>=$S$8,H18<=$T$8),$V$8,IF(AND(H18>=$S$9,H18<=$T$9),$V$9,IF(AND(H18>=$S$10,H18<=$T$10),$V$10,IF(AND(H18>=$S$11,H18<=$T$11),$V$11,IF(AND(H18>=$S$12,H18<=$T$12),$V$12,0)))))) -> 8 | L18: 4 | M18: =SUM(L18:L25) -> 24 | N18: =IF(F18<>"",SUMPRODUCT(K18:K25,L18:L25)/M18,"") -> 6.5 | O18: =SUM(M8:M25) -> 51 | P18: =SUMPRODUCT(M8:M25,N8:N25)/O18 -> 6.254902
D19: MA8251 | E19: =VLOOKUP(D19,'Course data'!$C$4:$H$65,2,FALSE) -> Mathematics II | F19: 21 | G19: 28 | H19: =F19+G19 -> 49 | J19: =IF(AND(H19>=$S$7,H19<=$T$7),$U$7,IF(AND(H19>=$S$8,H19<=$T$8),$U$8,IF(AND(H19>=$S$9,H19<=$T$9),$U$9,IF(AND(H19>=$S$10,H19<=$T$10),$U$10,IF(AND(H19>=$S$11,H19<=$T$11),$U$11,IF(AND(H19>=$S$12,H19<=$T$12),$U$12,0)))))) -> 0 | K19: =IF(AND(H19>=$S$7,H19<=$T$7),$V$7,IF(AND(H19>=$S$8,H19<=$T$8),$V$8,IF(AND(H19>=$S$9,H19<=$T$9),$V$9,IF(AND(H19>=$S$10,H19<=$T$10),$V$10,IF(AND(H19>=$S$11,H19<=$T$11),$V$11,IF(AND(H19>=$S$12,H19<=$T$12),$V$12,0)))))) -> 0 | L19: 4
D20: PH8253 | E20: =VLOOKUP(D20,'Course data'!$C$4:$H$65,2,FALSE) -> Physics for Information Science | F20: 29 | G20: 35 | H20: =F20+G20 -> 64 | J20: =IF(AND(H20>=$S$7,H20<=$T$7),$U$7,IF(AND(H20>=$S$8,H20<=$T$8),$U$8,IF(AND(H20>=$S$9,H20<=$T$9),$U$9,IF(AND(H20>=$S$10,H20<=$T$10),$U$10,IF(AND(H20>=$S$11,H20<=$T$11),$U$11,IF(AND(H20>=$S$12,H20<=$T$12),$U$12,0)))))) -> B+ | K20: =IF(AND(H20>=$S$7,H20<=$T$7),$V$7,IF(AND(H20>=$S$8,H20<=$T$8),$V$8,IF(AND(H20>=$S$9,H20<=$T$9),$V$9,IF(AND(H20>=$S$10,H20<=$T$10),$V$10,IF(AND(H20>=$S$11,H20<=$T$11),$V$11,IF(AND(H20>=$S$12,H20<=$T$12),$V$12,0)))))) -> 7 | L20: 3
D21: CS8202 | E21: =VLOOKUP(D21,'Course data'!$C$4:$H$65,2,FALSE) -> Principles of Computer Engineering | F21: 49 | G21: 47 | H21: =F21+G21 -> 96 | J21: =IF(AND(H21>=$S$7,H21<=$T$7),$U$7,IF(AND(H21>=$S$8,H21<=$T$8),$U$8,IF(AND(H21>=$S$9,H21<=$T$9),$U$9,IF(AND(H21>=$S$10,H21<=$T$10),$U$10,IF(AND(H21>=$S$11,H21<=$T$11),$U$11,IF(AND(H21>=$S$12,H21<=$T$12),$U$12,0)))))) -> O | K21: =IF(AND(H21>=$S$7,H21<=$T$7),$V$7,IF(AND(H21>=$S$8,H21<=$T$8),$V$8,IF(AND(H21>=$S$9,H21<=$T$9),$V$9,IF(AND(H21>=$S$10,H21<=$T$10),$V$10,IF(AND(H21>=$S$11,H21<=$T$11),$V$11,IF(AND(H21>=$S$12,H21<=$T$12),$V$12,0)))))) -> 10 | L21: 3
D22: CS8203 | E22: =VLOOKUP(D22,'Course data'!$C$4:$H$65,2,FALSE) -> Programming using C++ | F22: 30 | G22: 25 | H22: =F22+G22 -> 55 | J22: =IF(AND(H22>=$S$7,H22<=$T$7),$U$7,IF(AND(H22>=$S$8,H22<=$T$8),$U$8,IF(AND(H22>=$S$9,H22<=$T$9),$U$9,IF(AND(H22>=$S$10,H22<=$T$10),$U$10,IF(AND(H22>=$S$11,H22<=$T$11),$U$11,IF(AND(H22>=$S$12,H22<=$T$12),$U$12,0)))))) -> B | K22: =IF(AND(H22>=$S$7,H22<=$T$7),$V$7,IF(AND(H22>=$S$8,H22<=$T$8),$V$8,IF(AND(H22>=$S$9,H22<=$T$9),$V$9,IF(AND(H22>=$S$10,H22<=$T$10),$V$10,IF(AND(H22>=$S$11,H22<=$T$11),$V$11,IF(AND(H22>=$S$12,H22<=$T$12),$V$12,0)))))) -> 6 | L22: 3
D23: CS8201 | E23: =VLOOKUP(D23,'Course data'!$C$4:$H$65,2,FALSE) -> Digital Principles and System Design | F23: 47 | G23: 42 | H23: =F23+G23 -> 89 | J23: =IF(AND(H23>=$S$7,H23<=$T$7),$U$7,IF(AND(H23>=$S$8,H23<=$T$8),$U$8,IF(AND(H23>=$S$9,H23<=$T$9),$U$9,IF(AND(H23>=$S$10,H23<=$T$10),$U$10,IF(AND(H23>=$S$11,H23<=$T$11),$U$11,IF(AND(H23>=$S$12,H23<=$T$12),$U$12,0)))))) -> A+ | K23: =IF(AND(H23>=$S$7,H23<=$T$7),$V$7,IF(AND(H23>=$S$8,H23<=$T$8),$V$8,IF(AND(H23>=$S$9,H23<=$T$9),$V$9,IF(AND(H23>=$S$10,H23<=$T$10),$V$10,IF(AND(H23>=$S$11,H23<=$T$11),$V$11,IF(AND(H23>=$S$12,H23<=$T$12),$V$12,0)))))) -> 9 | L23: 3
C24: Practical | D24: CS8212 | E24: =VLOOKUP(D24,'Course data'!$C$4:$H$65,2,FALSE) -> Programming Laboratory | F24: 50 | G24: 25 | H24: =F24+G24 -> 75 | J24: =IF(AND(H24>=$S$7,H24<=$T$7),$U$7,IF(AND(H24>=$S$8,H24<=$T$8),$U$8,IF(AND(H24>=$S$9,H24<=$T$9),$U$9,IF(AND(H24>=$S$10,H24<=$T$10),$U$10,IF(AND(H24>=$S$11,H24<=$T$11),$U$11,IF(AND(H24>=$S$12,H24<=$T$12),$U$12,0)))))) -> A | K24: =IF(AND(H24>=$S$7,H24<=$T$7),$V$7,IF(AND(H24>=$S$8,H24<=$T$8),$V$8,IF(AND(H24>=$S$9,H24<=$T$9),$V$9,IF(AND(H24>=$S$10,H24<=$T$10),$V$10,IF(AND(H24>=$S$11,H24<=$T$11),$V$11,IF(AND(H24>=$S$12,H24<=$T$12),$V$12,0)))))) -> 8 | L24: 2
D25: CS8211 | E25: =VLOOKUP(D25,'Course data'!$C$4:$H$65,2,FALSE) -> Digital Laboratory | F25: 35 | G25: 22 | H25: =F25+G25 -> 57 | J25: =IF(AND(H25>=$S$7,H25<=$T$7),$U$7,IF(AND(H25>=$S$8,H25<=$T$8),$U$8,IF(AND(H25>=$S$9,H25<=$T$9),$U$9,IF(AND(H25>=$S$10,H25<=$T$10),$U$10,IF(AND(H25>=$S$11,H25<=$T$11),$U$11,IF(AND(H25>=$S$12,H25<=$T$12),$U$12,0)))))) -> B | K25: =IF(AND(H25>=$S$7,H25<=$T$7),$V$7,IF(AND(H25>=$S$8,H25<=$T$8),$V$8,IF(AND(H25>=$S$9,H25<=$T$9),$V$9,IF(AND(H25>=$S$10,H25<=$T$10),$V$10,IF(AND(H25>=$S$11,H25<=$T$11),$V$11,IF(AND(H25>=$S$12,H25<=$T$12),$V$12,0)))))) -> 6 | L25: 2
A26: 2 | B26: 3 | C26: Theory | D26: MA8351 | E26: =VLOOKUP(D26,'Course data'!$C$4:$H$65,2,FALSE) -> Algebra & Number Theory | F26: 19 | G26: 25 | H26: =F26+G26 -> 44 | I26: =AVERAGE(H26:H33) -> 78.875 | J26: =IF(AND(H26>=$S$7,H26<=$T$7),$U$7,IF(AND(H26>=$S$8,H26<=$T$8),$U$8,IF(AND(H26>=$S$9,H26<=$T$9),$U$9,IF(AND(H26>=$S$10,H26<=$T$10),$U$10,IF(AND(H26>=$S$11,H26<=$T$11),$U$11,IF(AND(H26>=$S$12,H26<=$T$12),$U$12,0)))))) -> 0 | K26: =IF(AND(H26>=$S$7,H26<=$T$7),$V$7,IF(AND(H26>=$S$8,H26<=$T$8),$V$8,IF(AND(H26>=$S$9,H26<=$T$9),$V$9,IF(AND(H26>=$S$10,H26<=$T$10),$V$10,IF(AND(H26>=$S$11,H26<=$T$11),$V$11,IF(AND(H26>=$S$12,H26<=$T$12),$V$12,0)))))) -> 0 | L26: 4 | M26: =SUM(L26:L33) -> 24 | N26: =IF(F26<>"",SUMPRODUCT(K26:K33,L26:L33)/M26,"") -> 7.4583333 | O26: =SUM(M8:M33) -> 75 | P26: =SUMPRODUCT(M8:M33,N8:N33)/O26 -> 6.64
D27: EC8303 | E27: =VLOOKUP(D27,'Course data'!$C$4:$H$65,2,FALSE) -> Electronic Devices and Circuits for Computer Engineers | F27: 38 | G27: 43 | H27: =F27+G27 -> 81 | J27: =IF(AND(H27>=$S$7,H27<=$T$7),$U$7,IF(AND(H27>=$S$8,H27<=$T$8),$U$8,IF(AND(H27>=$S$9,H27<=$T$9),$U$9,IF(AND(H27>=$S$10,H27<=$T$10),$U$10,IF(AND(H27>=$S$11,H27<=$T$11),$U$11,IF(AND(H27>=$S$12,H27<=$T$12),$U$12,0)))))) -> A+ | K27: =IF(AND(H27>=$S$7,H27<=$T$7),$V$7,IF(AND(H27>=$S$8,H27<=$T$8),$V$8,IF(AND(H27>=$S$9,H27<=$T$9),$V$9,IF(AND(H27>=$S$10,H27<=$T$10),$V$10,IF(AND(H27>=$S$11,H27<=$T$11),$V$11,IF(AND(H27>=$S$12,H27<=$T$12),$V$12,0)))))) -> 9 | L27: 3
D28: CS8302 | E28: =VLOOKUP(D28,'Course data'!$C$4:$H$65,2,FALSE) -> Data Structures | F28: 45 | G28: 49 | H28: =F28+G28 -> 94 | J28: =IF(AND(H28>=$S$7,H28<=$T$7),$U$7,IF(AND(H28>=$S$8,H28<=$T$8),$U$8,IF(AND(H28>=$S$9,H28<=$T$9),$U$9,IF(AND(H28>=$S$10,H28<=$T$10),$U$10,IF(AND(H28>=$S$11,H28<=$T$11),$U$11,IF(AND(H28>=$S$12,H28<=$T$12),$U$12,0)))))) -> O | K28: =IF(AND(H28>=$S$7,H28<=$T$7),$V$7,IF(AND(H28>=$S$8,H28<=$T$8),$V$8,IF(AND(H28>=$S$9,H28<=$T$9),$V$9,IF(AND(H28>=$S$10,H28<=$T$10),$V$10,IF(AND(H28>=$S$11,H28<=$T$11),$V$11,IF(AND(H28>=$S$12,H28<=$T$12),$V$12,0)))))) -> 10 | L28: 3
D29: CS8303 | E29: =VLOOKUP(D29,'Course data'!$C$4:$H$65,2,FALSE) -> Database Management Systems | F29: 35 | G29: 27 | H29: =F29+G29 -> 62 | J29: =IF(AND(H29>=$S$7,H29<=$T$7),$U$7,IF(AND(H29>=$S$8,H29<=$T$8),$U$8,IF(AND(H29>=$S$9,H29<=$T$9),$U$9,IF(AND(H29>=$S$10,H29<=$T$10),$U$10,IF(AND(H29>=$S$11,H29<=$T$11),$U$11,IF(AND(H29>=$S$12,H29<=$T$12),$U$12,0)))))) -> B+ | K29: =IF(AND(H29>=$S$7,H29<=$T$7),$V$7,IF(AND(H29>=$S$8,H29<=$T$8),$V$8,IF(AND(H29>=$S$9,H29<=$T$9),$V$9,IF(AND(H29>=$S$10,H29<=$T$10),$V$10,IF(AND(H29>=$S$11,H29<=$T$11),$V$11,IF(AND(H29>=$S$12,H29<=$T$12),$V$12,0)))))) -> 7 | L29: 3
D30: GE8351 | E30: =VLOOKUP(D30,'Course data'!$C$4:$H$65,2,FALSE) -> Environmental Science & Engineering | F30: 41 | G30: 43 | H30: =F30+G30 -> 84 | J30: =IF(AND(H30>=$S$7,H30<=$T$7),$U$7,IF(AND(H30>=$S$8,H30<=$T$8),$U$8,IF(AND(H30>=$S$9,H30<=$T$9),$U$9,IF(AND(H30>=$S$10,H30<=$T$10),$U$10,IF(AND(H30>=$S$11,H30<=$T$11),$U$11,IF(AND(H30>=$S$12,H30<=$T$12),$U$12,0)))))) -> A+ | K30: =IF(AND(H30>=$S$7,H30<=$T$7),$V$7,IF(AND(H30>=$S$8,H30<=$T$8),$V$8,IF(AND(H30>=$S$9,H30<=$T$9),$V$9,IF(AND(H30>=$S$10,H30<=$T$10),$V$10,IF(AND(H30>=$S$11,H30<=$T$11),$V$11,IF(AND(H30>=$S$12,H30<=$T$12),$V$12,0)))))) -> 9 | L30: 3
D31: CS8301 | E31: =VLOOKUP(D31,'Course data'!$C$4:$H$65,2,FALSE) -> Computer Architecture | F31: 47 | G31: 35 | H31: =F31+G31 -> 82 | J31: =IF(AND(H31>=$S$7,H31<=$T$7),$U$7,IF(AND(H31>=$S$8,H31<=$T$8),$U$8,IF(AND(H31>=$S$9,H31<=$T$9),$U$9,IF(AND(H31>=$S$10,H31<=$T$10),$U$10,IF(AND(H31>=$S$11,H31<=$T$11),$U$11,IF(AND(H31>=$S$12,H31<=$T$12),$U$12,0)))))) -> A+ | K31: =IF(AND(H31>=$S$7,H31<=$T$7),$V$7,IF(AND(H31>=$S$8,H31<=$T$8),$V$8,IF(AND(H31>=$S$9,H31<=$T$9),$V$9,IF(AND(H31>=$S$10,H31<=$T$10),$V$10,IF(AND(H31>=$S$11,H31<=$T$11),$V$11,IF(AND(H31>=$S$12,H31<=$T$12),$V$12,0)))))) -> 9 | L31: 4
C32: Practical | D32: CS8312 | E32: =VLOOKUP(D32,'Course data'!$C$4:$H$65,2,FALSE) -> Database Management Systems Laboratory | F32: 43 | G32: 45 | H32: =F32+G32 -> 88 | J32: =IF(AND(H32>=$S$7,H32<=$T$7),$U$7,IF(AND(H32>=$S$8,H32<=$T$8),$U$8,IF(AND(H32>=$S$9,H32<=$T$9),$U$9,IF(AND(H32>=$S$10,H32<=$T$10),$U$10,IF(AND(H32>=$S$11,H32<=$T$11),$U$11,IF(AND(H32>=$S$12,H32<=$T$12),$U$12,0)))))) -> A+ | K32: =IF(AND(H32>=$S$7,H32<=$T$7),$V$7,IF(AND(H32>=$S$8,H32<=$T$8),$V$8,IF(AND(H32>=$S$9,H32<=$T$9),$V$9,IF(AND(H32>=$S$10,H32<=$T$10),$V$10,IF(AND(H32>=$S$11,H32<=$T$11),$V$11,IF(AND(H32>=$S$12,H32<=$T$12),$V$12,0)))))) -> 9 | L32: 2
D33: CS8311 | E33: =VLOOKUP(D33,'Course data'!$C$4:$H$65,2,FALSE) -> Data Structures Laboratory | F33: 49 | G33: 47 | H33: =F33+G33 -> 96 | J33: =IF(AND(H33>=$S$7,H33<=$T$7),$U$7,IF(AND(H33>=$S$8,H33<=$T$8),$U$8,IF(AND(H33>=$S$9,H33<=$T$9),$U$9,IF(AND(H33>=$S$10,H33<=$T$10),$U$10,IF(AND(H33>=$S$11,H33<=$T$11),$U$11,IF(AND(H33>=$S$12,H33<=$T$12),$U$12,0)))))) -> O | K33: =IF(AND(H33>=$S$7,H33<=$T$7),$V$7,IF(AND(H33>=$S$8,H33<=$T$8),$V$8,IF(AND(H33>=$S$9,H33<=$T$9),$V$9,IF(AND(H33>=$S$10,H33<=$T$10),$V$10,IF(AND(H33>=$S$11,H33<=$T$11),$V$11,IF(AND(H33>=$S$12,H33<=$T$12),$V$12,0)))))) -> 10 | L33: 2
B34: 4 | C34: Theory | D34: EE8407 | E34: =VLOOKUP(D34,'Course data'!$C$4:$H$65,2,FALSE) -> Electrical Engineering and Control Systems | F34: 50 | G34: 50 | H34: =F34+G34 -> 100 | I34: =AVERAGE(H34:H41) -> 74.5 | J34: =IF(AND(H34>=$S$7,H34<=$T$7),$U$7,IF(AND(H34>=$S$8,H34<=$T$8),$U$8,IF(AND(H34>=$S$9,H34<=$T$9),$U$9,IF(AND(H34>=$S$10,H34<=$T$10),$U$10,IF(AND(H34>=$S$11,H34<=$T$11),$U$11,IF(AND(H34>=$S$12,H34<=$T$12),$U$12,0)))))) -> O | K34: =IF(AND(H34>=$S$7,H34<=$T$7),$V$7,IF(AND(H34>=$S$8,H34<=$T$8),$V$8,IF(AND(H34>=$S$9,H34<=$T$9),$V$9,IF(AND(H34>=$S$10,H34<=$T$10),$V$10,IF(AND(H34>=$S$11,H34<=$T$11),$V$11,IF(AND(H34>=$S$12,H34<=$T$12),$V$12,0)))))) -> 10 | L34: 3 | M34: =SUM(L34:L41) -> 25 | N34: =IF(F34<>"",SUMPRODUCT(K34:K41,L34:L41)/M34,"") -> 7.68 | O34: =SUM(M8:M41) -> 100 | P34: =SUMPRODUCT(M8:M41,N8:N41)/O34 -> 6.9
D35: CS8401 | E35: =VLOOKUP(D35,'Course data'!$C$4:$H$65,2,FALSE) -> Design & Analysis of Algorithms | F35: 43 | G35: 45 | H35: =F35+G35 -> 88 | J35: =IF(AND(H35>=$S$7,H35<=$T$7),$U$7,IF(AND(H35>=$S$8,H35<=$T$8),$U$8,IF(AND(H35>=$S$9,H35<=$T$9),$U$9,IF(AND(H35>=$S$10,H35<=$T$10),$U$10,IF(AND(H35>=$S$11,H35<=$T$11),$U$11,IF(AND(H35>=$S$12,H35<=$T$12),$U$12,0)))))) -> A+ | K35: =IF(AND(H35>=$S$7,H35<=$T$7),$V$7,IF(AND(H35>=$S$8,H35<=$T$8),$V$8,IF(AND(H35>=$S$9,H35<=$T$9),$V$9,IF(AND(H35>=$S$10,H35<=$T$10),$V$10,IF(AND(H35>=$S$11,H35<=$T$11),$V$11,IF(AND(H35>=$S$12,H35<=$T$12),$V$12,0)))))) -> 9 | L35: 4
D36: CS8451 | E36: =VLOOKUP(D36,'Course data'!$C$4:$H$65,2,FALSE) -> Operating Systems | F36: 39 | G36: 38 | H36: =F36+G36 -> 77 | J36: =IF(AND(H36>=$S$7,H36<=$T$7),$U$7,IF(AND(H36>=$S$8,H36<=$T$8),$U$8,IF(AND(H36>=$S$9,H36<=$T$9),$U$9,IF(AND(H36>=$S$10,H36<=$T$10),$U$10,IF(AND(H36>=$S$11,H36<=$T$11),$U$11,IF(AND(H36>=$S$12,H36<=$T$12),$U$12,0)))))) -> A | K36: =IF(AND(H36>=$S$7,H36<=$T$7),$V$7,IF(AND(H36>=$S$8,H36<=$T$8),$V$8,IF(AND(H36>=$S$9,H36<=$T$9),$V$9,IF(AND(H36>=$S$10,H36<=$T$10),$V$10,IF(AND(H36>=$S$11,H36<=$T$11),$V$11,IF(AND(H36>=$S$12,H36<=$T$12),$V$12,0)))))) -> 8 | L36: 3
D37: CS8402 | E37: =VLOOKUP(D37,'Course data'!$C$4:$H$65,2,FALSE) -> Java & Internet Programming | F37: 38 | G37: 35 | H37: =F37+G37 -> 73 | J37: =IF(AND(H37>=$S$7,H37<=$T$7),$U$7,IF(AND(H37>=$S$8,H37<=$T$8),$U$8,IF(AND(H37>=$S$9,H37<=$T$9),$U$9,IF(AND(H37>=$S$10,H37<=$T$10),$U$10,IF(AND(H37>=$S$11,H37<=$T$11),$U$11,IF(AND(H37>=$S$12,H37<=$T$12),$U$12,0)))))) -> A | K37: =IF(AND(H37>=$S$7,H37<=$T$7),$V$7,IF(AND(H37>=$S$8,H37<=$T$8),$V$8,IF(AND(H37>=$S$9,H37<=$T$9),$V$9,IF(AND(H37>=$S$10,H37<=$T$10),$V$10,IF(AND(H37>=$S$11,H37<=$T$11),$V$11,IF(AND(H37>=$S$12,H37<=$T$12),$V$12,0)))))) -> 8 | L37: 4
D38: MA8354 | E38: =VLOOKUP(D38,'Course data'!$C$4:$H$65,2,FALSE) -> Probability & Queueing Theory | F38: 49 | G38: 37 | H38: =F38+G38 -> 86 | J38: =IF(AND(H38>=$S$7,H38<=$T$7),$U$7,IF(AND(H38>=$S$8,H38<=$T$8),$U$8,IF(AND(H38>=$S$9,H38<=$T$9),$U$9,IF(AND(H38>=$S$10,H38<=$T$10),$U$10,IF(AND(H38>=$S$11,H38<=$T$11),$U$11,IF(AND(H38>=$S$12,H38<=$T$12),$U$12,0)))))) -> A+ | K38: =IF(AND(H38>=$S$7,H38<=$T$7),$V$7,IF(AND(H38>=$S$8,H38<=$T$8),$V$8,IF(AND(H38>=$S$9,H38<=$T$9),$V$9,IF(AND(H38>=$S$10,H38<=$T$10),$V$10,IF(AND(H38>=$S$11,H38<=$T$11),$V$11,IF(AND(H38>=$S$12,H38<=$T$12),$V$12,0)))))) -> 9 | L38: 4
D39: CS8452 | E39: =VLOOKUP(D39,'Course data'!$C$4:$H$65,2,FALSE) -> Software Engineering | F39: 30 | G39: 25 | H39: =F39+G39 -> 55 | J39: =IF(AND(H39>=$S$7,H39<=$T$7),$U$7,IF(AND(H39>=$S$8,H39<=$T$8),$U$8,IF(AND(H39>=$S$9,H39<=$T$9),$U$9,IF(AND(H39>=$S$10,H39<=$T$10),$U$10,IF(AND(H39>=$S$11,H39<=$T$11),$U$11,IF(AND(H39>=$S$12,H39<=$T$12),$U$12,0)))))) -> B | K39: =IF(AND(H39>=$S$7,H39<=$T$7),$V$7,IF(AND(H39>=$S$8,H39<=$T$8),$V$8,IF(AND(H39>=$S$9,H39<=$T$9),$V$9,IF(AND(H39>=$S$10,H39<=$T$10),$V$10,IF(AND(H39>=$S$11,H39<=$T$11),$V$11,IF(AND(H39>=$S$12,H39<=$T$12),$V$12,0)))))) -> 6 | L39: 3
C40: Practical | D40: CS8411 | E40: =VLOOKUP(D40,'Course data'!$C$4:$H$65,2,FALSE) -> Java & Internet Programming Laboratory | F40: 33 | G40: 40 | H40: =F40+G40 -> 73 | J40: =IF(AND(H40>=$S$7,H40<=$T$7),$U$7,IF(AND(H40>=$S$8,H40<=$T$8),$U$8,IF(AND(H40>=$S$9,H40<=$T$9),$U$9,IF(AND(H40>=$S$10,H40<=$T$10),$U$10,IF(AND(H40>=$S$11,H40<=$T$11),$U$11,IF(AND(H40>=$S$12,H40<=$T$12),$U$12,0)))))) -> A | K40: =IF(AND(H40>=$S$7,H40<=$T$7),$V$7,IF(AND(H40>=$S$8,H40<=$T$8),$V$8,IF(AND(H40>=$S$9,H40<=$T$9),$V$9,IF(AND(H40>=$S$10,H40<=$T$10),$V$10,IF(AND(H40>=$S$11,H40<=$T$11),$V$11,IF(AND(H40>=$S$12,H40<=$T$12),$V$12,0)))))) -> 8 | L40: 2
...

Sheet Course data
B3: Category | C3: Course Code | D3: Course Title | E3: L | F3: T | G3: P | H3: C
B4: Theory | C4: HS8151 | D4: Technical English I | E4: 3 | F4: 1 | G4: 0 | H4: 4 | I4: =SUM(H4:H13) -> 27
C5: MA8151 | D5: Mathematics I | E5: 3 | F5: 1 | G5: 0 | H5: 4
C6: PH8151 | D6: Engineering Physics | E6: 3 | F6: 0 | G6: 0 | H6: 3
C7: CY8151 | D7: Engineering Chemistry | E7: 3 | F7: 0 | G7: 0 | H7: 3
C8: GE8152 | D8: Engineering Graphics | E8: 2 | F8: 0 | G8: 3 | H8: 4
C9: GE8151 | D9: Computing Techniques | E9: 3 | F9: 0 | G9: 0 | H9: 3
B10: Practical | C10: PH8161 | D10: Physics Laboratory | E10: 0 | F10: 0 | G10: 2 | H10: 1
C11: CY8161 | D11: Chemistry Laboratory | E11: 0 | F11: 0 | G11: 2 | H11: 1
C12: GE8162 | D12: Engineering Practices Laboratory | E12: 0 | F12: 0 | G12: 3 | H12: 2
C13: GE8161 | D13: Computer Practice Laboratory | E13: 0 | F13: 0 | G13: 3 | H13: 2
B14: Theory | C14: HS8251 | D14: Technical English II | E14: 3 | F14: 1 | G14: 0 | H14: 4 | I14: =SUM(H14:H21) -> 24
C15: MA8251 | D15: Mathematics II | E15: 3 | F15: 1 | G15: 0 | H15: 4
C16: PH8253 | D16: Physics for Information Science | E16: 3 | F16: 0 | G16: 0 | H16: 3
C17: CS8202 | D17: Principles of Computer Engineering | E17: 3 | F17: 0 | G17: 0 | H17: 3
C18: CS8203 | D18: Programming using C++ | E18: 3 | F18: 0 | G18: 0 | H18: 3
C19: CS8201 | D19: Digital Principles and System Design | E19: 3 | F19: 0 | G19: 0 | H19: 3
B20: Practical | C20: CS8212 | D20: Programming Laboratory | E20: 0 | F20: 0 | G20: 3 | H20: 2
C21: CS8211 | D21: Digital Laboratory | E21: 0 | F21: 0 | G21: 3 | H21: 2
B22: Theory | C22: MA8351 | D22: Algebra & Number Theory | E22: 3 | F22: 1 | G22: 0 | H22: 4
C23: EC8303 | D23: Electronic Devices and Circuits for Computer Engineers | E23: 3 | F23: 0 | G23: 0 | H23: 3
C24: CS8302 | D24: Data Structures | E24: 3 | F24: 0 | G24: 0 | H24: 3
C25: CS8303 | D25: Database Management Systems | E25: 3 | F25: 0 | G25: 0 | H25: 3
C26: GE8351 | D26: Environmental Science & Engineering | E26: 3 | F26: 0 | G26: 0 | H26: 3
C27: CS8301 | D27: Computer Architecture | E27: 3 | F27: 1 | G27: 0 | H27: 4
B28: Practical | C28: CS8312 | D28: Database Management Systems Laboratory | E28: 0 | F28: 0 | G28: 3 | H28: 2
C29: CS8311 | D29: Data Structures Laboratory | E29: 0 | F29: 0 | G29: 3 | H29: 2
B30: Theory | C30: EE8407 | D30: Electrical Engineering and Control Systems | E30: 3 | F30: 0 | G30: 0 | H30: 3
C31: CS8401 | D31: Design & Analysis of Algorithms | E31: 3 | F31: 0 | G31: 2 | H31: 4
C32: CS8451 | D32: Operating Systems | E32: 3 | F32: 0 | G32: 0 | H32: 3
C33: CS8402 | D33: Java & Internet Programming | E33: 4 | F33: 0 | G33: 0 | H33: 4
C34: MA8354 | D34: Probability & Queueing Theory | E34: 3 | F34: 1 | G34: 0 | H34: 4
C35: CS8452 | D35: Software Engineering | E35: 3 | F35: 0 | G35: 0 | H35: 3
B36: Practical | C36: CS8411 | D36: Java & Internet Programming Laboratory | E36: 0 | F36: 0 | G36: 3 | H36: 2
C37: CS8461 | D37: Operating Systems Laboratory | E37: 0 | F37: 0 | G37: 3 | H37: 2
B38: Theory | C38: CS8551 | D38: Object Oriented Analysis & Design | E38: 3 | F38: 0 | G38: 0 | H38: 3
C39: CS8504 | D39: Theory of Computation | E39: 3 | F39: 0 | G39: 0 | H39: 3
C40: CS8503 | D40: System Software Internals | E40: 3 | F40: 0 | G40: 0 | H40: 3
C41: CS8502 | D41: Microprocessors & Micro Controllers | E41: 3 | F41: 0 | G41: 0 | H41: 3
C42: CS8501 | D42: Data Communication & Computer Networks | E42: 3 | F42: 1 | G42: 0 | H42: 4
...
